<?xml version="1.0" encoding="UTF-8"?>
<testng-results ignored="0" total="2" passed="1" failed="1" skipped="0">
    <reporter-output>
    </reporter-output>
    <suite started-at="2023-06-19T10:38:54 IST" name="Parallel Test Suite" finished-at="2023-06-19T10:39:50 IST"
           duration-ms="56249">
        <groups>
        </groups>
        <test started-at="2023-06-19T10:38:54 IST" name="ErrorValidation" finished-at="2023-06-19T10:39:50 IST"
              duration-ms="56249">
            <class name="tests.ErrorValidation">
                <test-method is-config="true"
                             signature="launchApplication()[pri:0, instance:tests.ErrorValidation@30e868be]"
                             started-at="2023-06-19T10:38:54 IST" name="launchApplication"
                             finished-at="2023-06-19T10:39:01 IST" duration-ms="6965" status="PASS">
                    <reporter-output>
                    </reporter-output>
                </test-method> <!-- launchApplication -->
                <test-method
                        signature="LoginErrorValidation(java.util.HashMap)[pri:0, instance:tests.ErrorValidation@30e868be]"
                        started-at="2023-06-19T10:39:01 IST" name="LoginErrorValidation" data-provider="allData"
                        finished-at="2023-06-19T10:39:05 IST" duration-ms="4513" status="FAIL">
                    <params>
                        <param index="0">
                            <value>
                                <![CDATA[{password=test@prajwal, loginErrorMsg=Login was unsuccessful. Please correct the errors and try again., signMsg=Welcome, , email=prajwal12345678@gmail.com}]]>
                            </value>
                        </param>
                    </params>
                    <exception class="java.lang.AssertionError">
                        <message>
                            <![CDATA[expected [Welcome, Please Sign In!] but found [Welcome, ]]]>
                        </message>
                        <full-stacktrace>
                            <![CDATA[java.lang.AssertionError: expected [Welcome, Please Sign In!] but found [Welcome, ]
at org.testng.Assert.fail(Assert.java:110)
at org.testng.Assert.failNotEquals(Assert.java:1577)
at org.testng.Assert.assertEqualsImpl(Assert.java:149)
at org.testng.Assert.assertEquals(Assert.java:131)
at org.testng.Assert.assertEquals(Assert.java:655)
at org.testng.Assert.assertEquals(Assert.java:665)
at tests.ErrorValidation.LoginErrorValidation(ErrorValidation.java:22)
at java.base/jdk.internal.reflect.NativeMethodAccessorImpl.invoke0(Native Method)
at java.base/jdk.internal.reflect.NativeMethodAccessorImpl.invoke(NativeMethodAccessorImpl.java:77)
at java.base/jdk.internal.reflect.DelegatingMethodAccessorImpl.invoke(DelegatingMethodAccessorImpl.java:43)
at java.base/java.lang.reflect.Method.invoke(Method.java:568)
at org.testng.internal.invokers.MethodInvocationHelper.invokeMethod(MethodInvocationHelper.java:139)
at org.testng.internal.invokers.TestInvoker.invokeMethod(TestInvoker.java:677)
at org.testng.internal.invokers.TestInvoker.invokeTestMethod(TestInvoker.java:221)
at org.testng.internal.invokers.MethodRunner.runInSequence(MethodRunner.java:50)
at org.testng.internal.invokers.TestInvoker$MethodInvocationAgent.invoke(TestInvoker.java:969)
at org.testng.internal.invokers.TestInvoker.invokeTestMethods(TestInvoker.java:194)
at org.testng.internal.invokers.TestMethodWorker.invokeTestMethods(TestMethodWorker.java:148)
at org.testng.internal.invokers.TestMethodWorker.run(TestMethodWorker.java:128)
at java.base/java.util.ArrayList.forEach(ArrayList.java:1511)
at org.testng.TestRunner.privateRun(TestRunner.java:829)
at org.testng.TestRunner.run(TestRunner.java:602)
at org.testng.SuiteRunner.runTest(SuiteRunner.java:437)
at org.testng.SuiteRunner.runSequentially(SuiteRunner.java:431)
at org.testng.SuiteRunner.privateRun(SuiteRunner.java:391)
at org.testng.SuiteRunner.run(SuiteRunner.java:330)
at org.testng.SuiteRunnerWorker.runSuite(SuiteRunnerWorker.java:52)
at org.testng.SuiteRunnerWorker.run(SuiteRunnerWorker.java:95)
at org.testng.TestNG.runSuitesSequentially(TestNG.java:1256)
at org.testng.TestNG.runSuitesLocally(TestNG.java:1176)
at org.testng.TestNG.runSuites(TestNG.java:1099)
at org.testng.TestNG.run(TestNG.java:1067)
at org.testng.remote.AbstractRemoteTestNG.run(AbstractRemoteTestNG.java:115)
at org.testng.remote.RemoteTestNG.initAndRun(RemoteTestNG.java:251)
at org.testng.remote.RemoteTestNG.main(RemoteTestNG.java:77)
]]>
                        </full-stacktrace>
                    </exception> <!-- java.lang.AssertionError -->
                    <reporter-output>
                    </reporter-output>
                </test-method> <!-- LoginErrorValidation -->
                <test-method is-config="true" signature="tearDown()[pri:0, instance:tests.ErrorValidation@30e868be]"
                             started-at="2023-06-19T10:39:06 IST" name="tearDown" finished-at="2023-06-19T10:39:06 IST"
                             duration-ms="303" status="PASS">
                    <reporter-output>
                    </reporter-output>
                </test-method> <!-- tearDown -->
                <test-method is-config="true"
                             signature="launchApplication()[pri:0, instance:tests.ErrorValidation@30e868be]"
                             started-at="2023-06-19T10:39:06 IST" name="launchApplication"
                             finished-at="2023-06-19T10:39:07 IST" duration-ms="1449" status="PASS">
                    <reporter-output>
                    </reporter-output>
                </test-method> <!-- launchApplication -->
                <test-method
                        signature="LoginErrorValidation(java.util.HashMap)[pri:0, instance:tests.ErrorValidation@30e868be]"
                        started-at="2023-06-19T10:39:07 IST" name="LoginErrorValidation" data-provider="allData"
                        finished-at="2023-06-19T10:39:50 IST" duration-ms="42598" status="PASS">
                    <params>
                        <param index="0">
                            <value>
                                <![CDATA[{password=test12345@prajwal, loginErrorMsg=Login was unsuccessful. Please correct the errors and try again., signMsg=Welcome, Please Sign In!, email=prajwal12345@gmail.com}]]>
                            </value>
                        </param>
                    </params>
                    <reporter-output>
                    </reporter-output>
                </test-method> <!-- LoginErrorValidation -->
                <test-method is-config="true" signature="tearDown()[pri:0, instance:tests.ErrorValidation@30e868be]"
                             started-at="2023-06-19T10:39:50 IST" name="tearDown" finished-at="2023-06-19T10:39:50 IST"
                             duration-ms="184" status="PASS">
                    <reporter-output>
                    </reporter-output>
                </test-method> <!-- tearDown -->
            </class> <!-- tests.ErrorValidation -->
        </test> <!-- ErrorValidation -->
    </suite> <!-- Parallel Test Suite -->
</testng-results>
